<?xml version="1.0" ?>
<robot name="mixed_robot">
    <!-- .......... GAZEBO PLUGINS ..................... -->
    <!-- ........................ Camera ........................ -->
    <gazebo reference="camera_link">
        <material>Gazebo/Grey</material>
        <plugin name="gazebo_ros_control" filename="libgazebo_ros_control.so">
            <robotNamespace>/</robotNamespace>
        </plugin>
    </gazebo>
    <!-- ........................ wheels ........................ -->
    <gazebo reference="left_wheel">
        <material>Gazebo/Indigo</material>
    </gazebo>
    <gazebo reference="right_wheel">
        <material>Gazebo/Indigo</material>
    </gazebo>  
    <gazebo reference="front_left_caster">
        <material>Gazebo/White</material>
    </gazebo>
    <gazebo reference="front_right_caster">
        <material>Gazebo/White</material>
    </gazebo>
    <gazebo reference="back_left_caster">
        <material>Gazebo/White</material>
    </gazebo>
    <gazebo reference="back_right_caster">
        <material>Gazebo/White</material>
    </gazebo>
    <!-- ........................ base ........................ -->
    <gazebo reference="base_chassis">
        <material>Gazebo/DarkGrey</material>
    </gazebo>
    <!-- ........................ base links ........................ -->
    <gazebo>
        <plugin name="gazebo_grasp_fix" filename="libgazebo_grasp_fix.so">
            <arm>
                <arm_name>arm</arm_name>
                <palm_link>link6</palm_link>
                <gripper_link>finger1</gripper_link>
                <gripper_link>finger2</gripper_link>
            </arm>
            <forces_angle_tolerance>100</forces_angle_tolerance>
            <update_rate>4</update_rate>
            <grip_count_threshold>4</grip_count_threshold>
            <max_grip_count>8</max_grip_count>
            <release_tolerance>0.005</release_tolerance>
            <disable_collisions_on_attach>false</disable_collisions_on_attach>
            <contact_topic>__default_topic__</contact_topic>
        </plugin>
    </gazebo>
    <!-- Differential drive. Set param "wheelSeparation" accordingly!-->
    <gazebo>
        <plugin filename="libgazebo_ros_diff_drive.so" name="differential_drive_controller">
            <legacyMode>false</legacyMode>
            <alwaysOn>true</alwaysOn>
            <updateRate>10</updateRate>
            <leftJoint>left_wheel_hinge</leftJoint>
            <rightJoint>right_wheel_hinge</rightJoint>
            <wheelSeparation>0.43</wheelSeparation>
            <wheelDiameter>0.16</wheelDiameter>
            <torque>20</torque>
            <commandTopic>cmd_vel</commandTopic>
            <odometryTopic>odom</odometryTopic>
            <odometryFrame>odom</odometryFrame>
            <robotBaseFrame>robot_footprint</robotBaseFrame>
            <publishWheelTF>false</publishWheelTF>
            <publishWheelJointState>true</publishWheelJointState>
            <rosDebugLevel>Debug</rosDebugLevel>
            <wheelAcceleration>1.0</wheelAcceleration>
            <wheelTorque>20</wheelTorque>
            <odometrySource>world</odometrySource>
            <publishTf>1</publishTf>
            <publishOdomTF>true</publishOdomTF>
        </plugin>
    </gazebo>
    <!-- RGBD Camera -->
    <gazebo reference="camera_link">
        <sensor name="camera1" type="depth">
            <always_on>1</always_on>
            <update_rate>30.0</update_rate>
            <visualize>true</visualize>
            <camera>
                <horizontal_fov>1.047</horizontal_fov>
                <image>
                    <width>800</width>
                    <height>800</height>
                    <format>R8G8B8</format>
                </image>
                <depth_camera />
                <clip>
                    <near>0.02</near>
                    <far>300</far>
                </clip>
                <noise>
                    <type>gaussian</type>
                    <!-- Noise is sampled independently per pixel on each frame.
               That pixel's noise value is added to each of its color
               channels, which at that point lie in the range [0,1]. -->
                    <mean>0.0</mean>
                    <stddev>0.007</stddev>
                </noise>
            </camera>
            <plugin filename="libgazebo_ros_openni_kinect.so" name="camera_controller">
                <alwaysOn>true</alwaysOn>
                <updateRate>10.0</updateRate>
                <cameraName>camera</cameraName>
                <frameName>camera_link_optical</frameName>
                <imageTopicName>rgb/image_raw</imageTopicName>
                <depthImageTopicName>depth/image_raw</depthImageTopicName>
                <pointCloudTopicName>depth/points</pointCloudTopicName>
                <cameraInfoTopicName>rgb/camera_info</cameraInfoTopicName>
                <depthImageCameraInfoTopicName>depth/camera_info</depthImageCameraInfoTopicName>
                <pointCloudCutoff>0.4</pointCloudCutoff>
                <hackBaseline>0.07</hackBaseline>
                <distortionK1>0.0</distortionK1>
                <distortionK2>0.0</distortionK2>
                <distortionK3>0.0</distortionK3>
                <distortionT1>0.0</distortionT1>
                <distortionT2>0.0</distortionT2>
                <CxPrime>0.0</CxPrime>
                <Cx>0.0</Cx>
                <Cy>0.0</Cy>
                <focalLength>0.0</focalLength>
            </plugin>
        </sensor>
    </gazebo>
    <!-- hokuyo -->
    <gazebo reference="hokuyo">
        <sensor name="head_hokuyo_sensor" type="ray">
            <pose>0 0 0 0 0 0</pose>
            <visualize>false</visualize>
            <update_rate>40</update_rate>
            <ray>
                <scan>
                    <horizontal>
                        <samples>720</samples>
                        <resolution>1</resolution>
                        <min_angle>-1.570796</min_angle>
                        <max_angle>1.570796</max_angle>
                    </horizontal>
                </scan>
                <range>
                    <min>0.10</min>
                    <max>30.0</max>
                    <resolution>0.01</resolution>
                </range>
                <noise>
                    <type>gaussian</type>
                    <!-- Noise parameters based on published spec for Hokuyo laser
               achieving "+-30mm" accuracy at range < 10m.  A mean of 0.0m and
               stddev of 0.01m will put 99.7% of samples within 0.03m of the true
               reading. -->
                    <mean>0.0</mean>
                    <stddev>0.01</stddev>
                </noise>
            </ray>
            <plugin filename="libgazebo_ros_laser.so" name="gazebo_ros_head_hokuyo_controller">
                <topicName>/scan</topicName>
                <frameName>hokuyo</frameName>
            </plugin>
        </sensor>
    </gazebo>
    <!-- Robot definitions -->
    <!-- ROBOT BASE LINK -->
    <link name="robot_footprint" />
    <!-- arm BASE LINK -->
    <link name="arm_base_link">
        <!--    <visual>
            <origin rpy="0 0 0" xyz="0 0 0" />
            <material name="silver">
                <color rgba="0.75 0.75 0.75 1" />
            </material>
        </visual>
        <collision>
            <origin rpy="0 0 0" xyz="0 0 0" />
            <geometry>
                <cylinder length="0.02" radius="0.3" />
            </geometry>
        </collision>
        <inertial>
            <mass value="0.1" />
            <inertia ixx="0.03" iyy="0.03" izz="0.03" ixy="0.0" ixz="0.0" iyz="0.0" />
            <origin xyz="0 0 0" rpy="0 0 0" />
        </inertial> 
    -->
    </link>
    <link name="base_chassis">
        <pose>0 0 0 0 0 0</pose>
        <inertial>
            <mass value="15" />
            <origin rpy=" 0 0 0" xyz="0 0 0" />
            <inertia ixx="0.22812500000000002" ixy="0" ixz="0" iyy="0.340625" iyz="0" izz="0.5125000000000001" />
        </inertial>
        <collision name="collision">
            <origin rpy=" 0 0 0" xyz="0 0 0" />
            <geometry>
                <box size="0.5 0.4 0.15" />
            </geometry>
        </collision>
        <visual name="base_chassis_visual">
            <origin rpy=" 0 0 0" xyz="0 0 0" />
            <geometry>
                <box size="0.5 0.4 0.15" />
            </geometry>
        </visual>
    </link>
    <!-- joint -->
    <joint name="base_link_joint" type="fixed">
        <parent link="base_chassis" />
        <child link="arm_base_link" />
        <origin rpy="0 0 0" xyz="0 0 0.075" />
    </joint>
    <joint name="robot_footprint_joint" type="fixed">
        <origin rpy="0 0 0" xyz="0 0 0.1175" />
        <parent link="robot_footprint" />
        <child link="base_chassis" />
    </joint>
    <!-- Wheels definitions -->
    <link name="left_wheel">
        <inertial>
            <mass value="1.0" />
            <origin rpy=" 0 1.5707 1.5707" xyz="0.0 0 0" />
            <inertia ixx="0.0016333333333333332" ixy="0" ixz="0" iyy="0.0016333333333333332" iyz="0" izz="0.0032" />
        </inertial>
        <collision name="collision">
            <origin rpy=" 0 1.5707 1.5707" xyz="0.0 0 0" />
            <geometry>
                <cylinder length="0.02" radius="0.08" />
            </geometry>
        </collision>
        <visual name="left_wheel_visual">
            <origin rpy=" 0 1.5707 1.5707" xyz="0.0 0 0" />
            <geometry>
                <cylinder length="0.02" radius="0.08" />
            </geometry>
        </visual>
    </link>
    <joint name="left_wheel_hinge" type="continuous">
        <origin rpy="0 0 0" xyz="0 0.21500000000000002 -0.0375" />
        <child link="left_wheel" />
        <parent link="base_chassis" />
        <axis rpy="0 0 0" xyz="0 1 0" />
        <dynamics damping="0" friction="1.0" />
    </joint>
    <link name="right_wheel">
        <inertial>
            <mass value="1.0" />
            <origin rpy=" 0 1.5707 1.5707" xyz="0.0 0 0" />
            <inertia ixx="0.0016333333333333332" ixy="0" ixz="0" iyy="0.0016333333333333332" iyz="0" izz="0.0032" />
        </inertial>
        <collision name="collision">
            <origin rpy=" 0 1.5707 1.5707" xyz="0.0 0 0" />
            <geometry>
                <cylinder length="0.02" radius="0.08" />
            </geometry>
        </collision>
        <visual name="right_wheel_visual">
            <origin rpy=" 0 1.5707 1.5707" xyz="0.0 0 0" />
            <geometry>
                <cylinder length="0.02" radius="0.08" />
            </geometry>
        </visual>
    </link>
    <joint name="right_wheel_hinge" type="continuous">
        <origin rpy="0 0 0" xyz="0 -0.21500000000000002 -0.0375" />
        <child link="right_wheel" />
        <parent link="base_chassis" />
        <axis rpy="0 0 0" xyz="0 1 0" />
        <dynamics damping="0" friction="1.0" />
    </joint>
    <link name="front_left_caster">
        <inertial>
            <mass value="0.1" />
            <origin rpy=" 0 0 0" xyz="0 0 0" />
            <inertia ixx="1.8062500000000002e-05" ixy="0" ixz="0" iyy="1.8062500000000002e-05" iyz="0" izz="1.8062500000000002e-05" />
        </inertial>
        <collision name="collision">
            <origin rpy=" 0 0 0" xyz="0 0 0" />
            <geometry>
                <sphere radius="0.02125" />
            </geometry>
        </collision>
        <visual name="front_left_caster_visual">
            <origin rpy=" 0 0 0" xyz="0 0 0" />
            <geometry>
                <sphere radius="0.02125" />
            </geometry>
        </visual>
    </link>
    <joint name="front_left_caster_hinge" type="continuous">
        <origin rpy="0 0 0" xyz="0.234375 0.184375 -0.09625" />
        <child link="front_left_caster" />
        <parent link="base_chassis" />
        <axis rpy="0 0 0" xyz="1 1 1" />
        <dynamics damping="0" friction="0" />
    </joint>
    <link name="front_right_caster">
        <inertial>
            <mass value="0.1" />
            <origin rpy=" 0 0 0" xyz="0 0 0" />
            <inertia ixx="1.8062500000000002e-05" ixy="0" ixz="0" iyy="1.8062500000000002e-05" iyz="0" izz="1.8062500000000002e-05" />
        </inertial>
        <collision name="collision">
            <origin rpy=" 0 0 0" xyz="0 0 0" />
            <geometry>
                <sphere radius="0.02125" />
            </geometry>
        </collision>
        <visual name="front_right_caster_visual">
            <origin rpy=" 0 0 0" xyz="0 0 0" />
            <geometry>
                <sphere radius="0.02125" />
            </geometry>
        </visual>
    </link>
    <joint name="front_right_caster_hinge" type="continuous">
        <origin rpy="0 0 0" xyz="0.234375 -0.184375 -0.09625" />
        <child link="front_right_caster" />
        <parent link="base_chassis" />
        <axis rpy="0 0 0" xyz="1 1 1" />
        <dynamics damping="0" friction="0" />
    </joint>
    <link name="back_left_caster">
        <inertial>
            <mass value="0.1" />
            <origin rpy=" 0 0 0" xyz="0 0 0" />
            <inertia ixx="1.8062500000000002e-05" ixy="0" ixz="0" iyy="1.8062500000000002e-05" iyz="0" izz="1.8062500000000002e-05" />
        </inertial>
        <collision name="collision">
            <origin rpy=" 0 0 0" xyz="0 0 0" />
            <geometry>
                <sphere radius="0.02125" />
            </geometry>
        </collision>
        <visual name="back_left_caster_visual">
            <origin rpy=" 0 0 0" xyz="0 0 0" />
            <geometry>
                <sphere radius="0.02125" />
            </geometry>
        </visual>
    </link>
    <joint name="back_left_caster_hinge" type="continuous">
        <origin rpy="0 0 0" xyz="-0.234375 0.184375 -0.09625" />
        <child link="back_left_caster" />
        <parent link="base_chassis" />
        <axis rpy="0 0 0" xyz="1 1 1" />
        <dynamics damping="0" friction="0" />
    </joint>
    <link name="back_right_caster">
        <inertial>
            <mass value="0.1" />
            <origin rpy=" 0 0 0" xyz="0 0 0" />
            <inertia ixx="1.8062500000000002e-05" ixy="0" ixz="0" iyy="1.8062500000000002e-05" iyz="0" izz="1.8062500000000002e-05" />
        </inertial>
        <collision name="collision">
            <origin rpy=" 0 0 0" xyz="0 0 0" />
            <geometry>
                <sphere radius="0.02125" />
            </geometry>
        </collision>
        <visual name="back_right_caster_visual">
            <origin rpy=" 0 0 0" xyz="0 0 0" />
            <geometry>
                <sphere radius="0.02125" />
            </geometry>
        </visual>
    </link>
    <joint name="back_right_caster_hinge" type="continuous">
        <origin rpy="0 0 0" xyz="-0.234375 -0.184375 -0.09625" />
        <child link="back_right_caster" />
        <parent link="base_chassis" />
        <axis rpy="0 0 0" xyz="1 1 1" />
        <dynamics damping="0" friction="0" />
    </joint>
    <link name="left_container_side">
        <pose>0 0 0 0 0 0</pose>
        <inertial>
            <mass value="0.01" />
            <origin rpy=" 0 0 0" xyz="0 0 0" />
            <inertia ixx="8.416666666666669e-06" ixy="0" ixz="0" iyy="0.00021666666666666668" iyz="0" izz="0.00020841666666666665" />
        </inertial>
        <collision name="collision">
            <origin rpy=" 0 0 0" xyz="0 0 0" />
            <geometry>
                <box size="0.5 0.01 0.1" />
            </geometry>
        </collision>
        <visual name="left_container_side_visual">
            <origin rpy=" 0 0 0" xyz="0 0 0" />
            <geometry>
                <box size="0.5 0.01 0.1" />
            </geometry>
        </visual>
    </link>
    <joint name="left_container_side_hinge" type="fixed">
        <origin rpy="0 0 0" xyz="0.0 0.195 0.125" />
        <child link="left_container_side" />
        <parent link="base_chassis" />
    </joint>
    <link name="right_container_side">
        <pose>0 0 0 0 0 0</pose>
        <inertial>
            <mass value="0.01" />
            <origin rpy=" 0 0 0" xyz="0 0 0" />
            <inertia ixx="8.416666666666669e-06" ixy="0" ixz="0" iyy="0.00021666666666666668" iyz="0" izz="0.00020841666666666665" />
        </inertial>
        <collision name="collision">
            <origin rpy=" 0 0 0" xyz="0 0 0" />
            <geometry>
                <box size="0.5 0.01 0.1" />
            </geometry>
        </collision>
        <visual name="right_container_side_visual">
            <origin rpy=" 0 0 0" xyz="0 0 0" />
            <geometry>
                <box size="0.5 0.01 0.1" />
            </geometry>
        </visual>
    </link>
    <joint name="right_container_side_hinge" type="fixed">
        <origin rpy="0 0 0" xyz="0.0 -0.195 0.125" />
        <child link="right_container_side" />
        <parent link="base_chassis" />
    </joint>
    <link name="front_container_side">
        <pose>0 0 0 0 0 0</pose>
        <inertial>
            <mass value="0.01" />
            <origin rpy=" 0 0 0" xyz="0 0 0" />
            <inertia ixx="0.0001416666666666667" ixy="0" ixz="0" iyy="1.666666666666667e-05" iyz="0" izz="0.0001416666666666667" />
        </inertial>
        <collision name="collision">
            <origin rpy=" 0 0 0" xyz="0 0 0" />
            <geometry>
                <box size="0.1 0.4 0.1" />
            </geometry>
        </collision>
        <visual name="front_container_side_visual">
            <origin rpy=" 0 0 0" xyz="0 0 0" />
            <geometry>
                <box size="0.1 0.4 0.1" />
            </geometry>
        </visual>
    </link>
    <joint name="front_container_side_hinge" type="fixed">
        <origin rpy="0 0 0" xyz="0.2 0.0 0.125" />
        <child link="front_container_side" />
        <parent link="base_chassis" />
    </joint>
    <link name="back_container_side">
        <pose>0 0 0 0 0 0</pose>
        <inertial>
            <mass value="0.01" />
            <origin rpy=" 0 0 0" xyz="0 0 0" />
            <inertia ixx="0.0001416666666666667" ixy="0" ixz="0" iyy="8.416666666666669e-06" iyz="0" izz="0.0001334166666666667" />
        </inertial>
        <collision name="collision">
            <origin rpy=" 0 0 0" xyz="0 0 0" />
            <geometry>
                <box size="0.01 0.4 0.1" />
            </geometry>
        </collision>
        <visual name="back_container_side_visual">
            <origin rpy=" 0 0 0" xyz="0 0 0" />
            <geometry>
                <box size="0.01 0.4 0.1" />
            </geometry>
        </visual>
    </link>
    <joint name="back_container_side_hinge" type="fixed">
        <origin rpy="0 0 0" xyz="-0.245 0.0 0.125" />
        <child link="back_container_side" />
        <parent link="base_chassis" />
    </joint>
    <!-- ### CAMERA ### -->
    <link name="camera_link">
        <inertial>
            <mass value="0.1" />
            <origin rpy=" 0 0 0" xyz="0.0 0 0" />
            <inertia ixx="4.166666666666668e-05" ixy="0" ixz="0" iyy="4.166666666666668e-05" iyz="0" izz="4.166666666666668e-05" />
        </inertial>
        <collision name="camera_collision">
            <origin rpy=" 0 0 0" xyz="0 0 0" />
            <geometry>
                <box size="0.05 0.05 0.05" />
            </geometry>
        </collision>
        <visual name="camera_link_visual">
            <origin rpy=" 0 0 0" xyz="0 0 0" />
            <geometry>
                <box size="0.05 0.05 0.05" />
            </geometry>
        </visual>
    </link>
    <link name="camera_link_optical" />
    <joint name="camera_joint" type="fixed">
        <origin rpy="0 0 0" xyz="0.275 0 0.15" />
        <child link="camera_link" />
        <parent link="base_chassis" />
        <axis rpy="0 0 0.02" xyz="0 1 0" />
    </joint>
    <joint name="camera_optical_joint" type="fixed">
        <origin rpy="-1.5707 0 -1.5707" xyz="0 0 0" />
        <parent link="camera_link" />
        <child link="camera_link_optical" />
    </joint>
    <!-- ### LIDAR ### -->
    <link name="hokuyo">
        <inertial>
            <mass value="0.00001" />
            <origin rpy=" 0 0 0" xyz="0.0 0 0" />
            <inertia ixx="1.666666666666667e-08" ixy="0" ixz="0" iyy="1.666666666666667e-08" iyz="0" izz="1.666666666666667e-08" />
        </inertial>
        <collision name="hokuyo_collision">
            <origin rpy=" 0 0 0" xyz="0 0 0" />
            <geometry>
                <box size="0.1 0.1 0.1" />
            </geometry>
        </collision>
        <visual name="hokuyo_visual">
            <origin rpy=" 0 0 0" xyz="0 0 0" />
            <geometry>
                <mesh filename="package://my_simulations/models/meshes/hokuyo.dae" />
            </geometry>
        </visual>
    </link>
    <joint name="hokuyo_joint" type="fixed">
        <origin rpy="0 0 0" xyz="0.2 0 0.225" />
        <child link="hokuyo" />
        <parent link="base_chassis" />
        <axis rpy="0 0 0" xyz="0 1 0" />
    </joint>
    <material name="yellow">
        <color rgba="0.0 0.8 0.0 1.0" />
    </material>
    <material name="red">
        <color rgba="0.0 0.8 0.0 1.0" />
    </material>
    <material name="black">
        <color rgba="0.0 0.0 0.0 1.0" />
    </material>
    <material name="blue">
        <color rgba="0.0 0.0 0.0 1.0" />
    </material>
    <material name="white">
        <color rgba="0.0 0.0 0.0 1.0" />
    </material>
    <!-- LINK 1 -->
    <link name="link1">
        <visual>
            <origin rpy="0 0 0" xyz="0 0 0.075" />
            <!-- linknte paathi distance -->
            <geometry>
                <cylinder length="0.10" radius="0.05" />
            </geometry>
            <material name="silver">
                <color rgba="0.75 0.75 0.75 1" />
            </material>
        </visual>
        <collision>
            <origin rpy="0 0 0" xyz="0 0 0.075" />
            <geometry>
                <cylinder length="0.10" radius="0.05" />
            </geometry>
        </collision>
        <inertial>
            <mass value="0.1" />
            <inertia ixx="0.03" iyy="0.03" izz="0.03" ixy="0.0" ixz="0.0" iyz="0.0" />
            <origin xyz="0 0 0" rpy="0 0 0" />
        </inertial>
    </link>
    <gazebo reference="link1">
        <material>Gazebo/Black</material>
        <turnGravityOff>false</turnGravityOff>
    </gazebo>
    <!-- JOINT 1 -->
    <joint name="joint1" type="continuous">
        <origin rpy="0 0 0" xyz="0 0 0.0 " />
        <!--parent linknte distance -->
        <parent link="arm_base_link" />
        <child link="link1" />
        <axis xyz="0 0 1" />
    </joint>
    <!-- LINK 2 -->
    <link name="link2">
        <visual>
            <origin rpy="0 0 0" xyz="0 0 0.15" />
            <geometry>
                <cylinder length="0.30" radius="0.03" />
            </geometry>
            <material name="silver">
                <color rgba="0.75 0.75 0.75 1" />
            </material>
        </visual>
        <collision>
            <origin rpy="0 0 0" xyz="0 0 0.15" />
            <geometry>
                <cylinder length="0.30" radius="0.03" />
            </geometry>
        </collision>
        <inertial>
            <mass value="0.1" />
            <inertia ixx="0.03" iyy="0.03" izz="0.03" ixy="0.0" ixz="0.0" iyz="0.0" />
            <origin xyz="0 0 0" rpy="0 0 0" />
        </inertial>
    </link>
    <gazebo reference="link2">
        <material>Gazebo/Blue</material>
        <turnGravityOff>false</turnGravityOff>
    </gazebo>
    <!-- JOINT 2 -->
    <joint name="joint2" type="revolute">
        <origin rpy="0 0 0" xyz="0 0 0.08" />
        <parent link="link1" />
        <child link="link2" />
        <axis xyz="0 1 0" />
        <limit lower="-1.57" upper="1.57" effort="100" velocity="1" />
        <dynamics damping="0.01" friction="0.01" />
    </joint>
    <!-- LINK 3 -->
    <link name="link3">
        <visual>
            <origin rpy="0 0 0" xyz="0 0 0.15" />
            <geometry>
                <cylinder length="0.30" radius="0.03" />
            </geometry>
            <material name="silver">
                <color rgba="0.75 0.75 0.75 1" />
            </material>
        </visual>
        <collision>
            <origin rpy="0 0 0" xyz="0 0 0.15" />
            <geometry>
                <cylinder length="0.30" radius="0.03" />
            </geometry>
        </collision>
        <inertial>
            <mass value="0.1" />
            <inertia ixx="0.03" iyy="0.03" izz="0.03" ixy="0.0" ixz="0.0" iyz="0.0" />
            <origin xyz="0 0 0" rpy="0 0 0" />
        </inertial>
    </link>
    <gazebo reference="link3">
        <material>Gazebo/Black</material>
        <turnGravityOff>false</turnGravityOff>
    </gazebo>
    <!-- JOINT 3 -->
    <joint name="joint3" type="revolute">
        <origin rpy="0 0 0" xyz="0 0 0.28" />
        <parent link="link2" />
        <child link="link3" />
        <axis xyz="0 1 0" />
        <limit lower="-2.57" upper="2.57" effort="100" velocity="1" />
        <dynamics damping="0.01" friction="0.01" />
    </joint>
    <!-- LINK 4 -->
    <link name="link4">
        <visual>
            <origin rpy="0 0 0" xyz="0 0 0.05" />
            <geometry>
                <box size="0.03 0.03 0.1" />
            </geometry>
            <material name="silver">
                <color rgba="0.75 0.75 0.75 1" />
            </material>
        </visual>
        <collision>
            <origin rpy="0 0 0" xyz="0 0 0.05" />
            <geometry>
                <box size="0.03 0.03 0.1" />
            </geometry>
        </collision>
        <inertial>
            <mass value="0.1" />
            <inertia ixx="0.03" iyy="0.03" izz="0.03" ixy="0.0" ixz="0.0" iyz="0.0" />
            <origin xyz="0 0 0" rpy="0 0 0" />
        </inertial>
    </link>
    <gazebo reference="link4">
        <material>Gazebo/Blue</material>
        <turnGravityOff>false</turnGravityOff>
    </gazebo>
    <!-- JOINT 4 -->
    <joint name="joint4" type="revolute">
        <origin rpy="0 0 0" xyz="0 0 0.28" />
        <parent link="link3" />
        <child link="link4" />
        <axis xyz="0 0 1" />
        <limit lower="-3.14" upper="3.14" effort="100" velocity="1" />
        <dynamics damping="0.01" friction="0.01" />
    </joint>
    <!-- LINK 5 -->
    <link name="link5">
        <visual>
            <origin rpy="0 0 0" xyz="0 0 0.05" />
            <geometry>
                <box size="0.03 0.03 0.1" />
            </geometry>
            <material name="silver">
                <color rgba="0.75 0.75 0.75 1" />
            </material>
        </visual>
        <collision>
            <origin rpy="0 0 0" xyz="0 0 0.05" />
            <geometry>
                <box size="0.03 0.03 0.1" />
            </geometry>
        </collision>
        <inertial>
            <mass value="0.1" />
            <inertia ixx="0.03" iyy="0.03" izz="0.03" ixy="0.0" ixz="0.0" iyz="0.0" />
            <origin xyz="0 0 0" rpy="0 0 0" />
        </inertial>
    </link>
    <gazebo reference="link5">
        <material>Gazebo/Black</material>
        <turnGravityOff>false</turnGravityOff>
    </gazebo>
    <!-- JOINT 5 -->
    <joint name="joint5" type="revolute">
        <origin rpy="0 0 0" xyz="0 0 0.08" />
        <parent link="link4" />
        <child link="link5" />
        <axis xyz="0 1 0" />
        <limit lower="-2.57" upper="2.57" effort="100" velocity="1" />
        <dynamics damping="0.01" friction="0.01" />
    </joint>
    <!-- LINK 6 -->
    <link name="link6">
        <visual>
            <origin rpy="0 0 0" xyz="0 0 0.05" />
            <geometry>
                <cylinder length="0.10" radius="0.04" />
            </geometry>
            <material name="silver">
                <color rgba="0.75 0.75 0.75 1" />
            </material>
            <material name="Blue" />
        </visual>
        <collision>
            <origin rpy="0 0 0" xyz="0 0 0.05" />
            <geometry>
                <cylinder length="0.10" radius="0.04" />
            </geometry>
        </collision>
        <inertial>
            <mass value="0.1" />
            <inertia ixx="0.03" iyy="0.03" izz="0.03" ixy="0.0" ixz="0.0" iyz="0.0" />
            <origin xyz="0 0 0" rpy="0 0 0" />
        </inertial>
    </link>
    <gazebo reference="link6">
        <material>Gazebo/Blue</material>
        <turnGravityOff>false</turnGravityOff>
    </gazebo>
    <!-- JOINT 6 -->
    <joint name="joint6" type="revolute">
        <origin rpy="0 0 0" xyz="0 0 0.08" />
        <parent link="link5" />
        <child link="link6" />
        <axis xyz="1 0 0" />
        <limit lower="-2.57" upper="2.57" effort="100" velocity="1" />
        <dynamics damping="0.01" friction="0.01" />
    </joint>
    <link name="finger1">
        <visual>
            <geometry>
                <box size="0.01 0.01 .05" />
            </geometry>
            <material name="silver">
                <color rgba="0.75 0.75 0.75 1" />
            </material>
            <origin rpy="0 0 0" xyz="0.005 0.005 0.025 " />
        </visual>
        <collision>
            <geometry>
                <box size="0.01 0.01 .05" />
            </geometry>
            <origin rpy="0 0 0" xyz="0.005 0.005 0.025" />
        </collision>
        <inertial>
            <mass value="0.1" />
            <inertia ixx="0.03" iyy="0.03" izz="0.03" ixy="0.0" ixz="0.0" iyz="0.0" />
            <origin xyz="0 0 0" rpy="0 0 0" />
        </inertial>
    </link>
    <gazebo reference="finger1">
        <material>Gazebo/White</material>
        <turnGravityOff>false</turnGravityOff>
    </gazebo>
    <joint name="f_joint1" type="prismatic">
        <axis xyz="0 1 0" />
        <limit effort="20" lower="0.0" upper="0.020" velocity="0.2" />
        <parent link="link6" />
        <child link="finger1" />
        <origin rpy="0 0 0" xyz="0 -0.025 0.1" />
    </joint>
    <link name="finger2">
        <visual>
            <geometry>
                <box size="0.01 0.01 .05" />
            </geometry>
            <material name="silver">
                <color rgba="0.75 0.75 0.75 1" />
            </material>
            <origin rpy="0 0 0" xyz="0.005 0.005 0.025 " />
        </visual>
        <collision>
            <geometry>
                <box size="0.01 0.01 .05" />
            </geometry>
            <origin rpy="0 0 0" xyz="0.005 0.005 0.025 " />
        </collision>
        <inertial>
            <mass value="0.1" />
            <inertia ixx="0.03" iyy="0.03" izz="0.03" ixy="0.0" ixz="0.0" iyz="0.0" />
            <origin xyz="0 0 0" rpy="0 0 0" />
        </inertial>
    </link>
    <gazebo reference="finger2">
        <material>Gazebo/White</material>
        <turnGravityOff>false</turnGravityOff>
    </gazebo>
    <joint name="f_joint2" type="prismatic">
        <axis xyz="0 1 0" />
        <limit effort="20" lower="-0.020" upper="0" velocity="0.2" />
        <parent link="link6" />
        <child link="finger2" />
        <origin rpy="0 0 0" xyz="0 0.025 0.1" />
    </joint>
    <!-- TRANSMISTION -->
    <!-- ...................................... grip Effort ...................................... -->
    <transmission name="trans_f_joint1">
        <type>transmission_interface/SimpleTransmission</type>
        <joint name="f_joint1">
            <hardwareInterface>hardware_interface/EffortJointInterface</hardwareInterface>
        </joint>
        <actuator name="f_joint1_motor">
            <hardwareInterface>hardware_interface/EffortJointInterface</hardwareInterface>
            <mechanicalReduction>1</mechanicalReduction>
        </actuator>
    </transmission>
    <transmission name="trans_f_joint2">
        <type>transmission_interface/SimpleTransmission</type>
        <joint name="f_joint2">
            <hardwareInterface>hardware_interface/EffortJointInterface</hardwareInterface>
        </joint>
        <actuator name="f_joint2_motor">
            <hardwareInterface>hardware_interface/EffortJointInterface</hardwareInterface>
            <mechanicalReduction>1</mechanicalReduction>
        </actuator>
    </transmission>
    <!-- ...................................... grip velocity ...................................... -->
<!--
    <transmission name="trans_f_joint1">
        <type>transmission_interface/SimpleTransmission</type>
        <joint name="f_joint1">
            <hardwareInterface>hardware_interface/VelocityJointInterface</hardwareInterface>
        </joint>
        <actuator name="f_joint1_motor">
            <hardwareInterface>hardware_interface/VelocityJointInterface</hardwareInterface>
            <mechanicalReduction>1</mechanicalReduction>
        </actuator>
    </transmission>
    <transmission name="trans_f_joint2">
        <type>transmission_interface/SimpleTransmission</type>
        <joint name="f_joint2">
            <hardwareInterface>hardware_interface/VelocityJointInterface</hardwareInterface>
        </joint>
        <actuator name="f_joint2_motor">
            <hardwareInterface>hardware_interface/VelocityJointInterface</hardwareInterface>
            <mechanicalReduction>1</mechanicalReduction>
        </actuator>
    </transmission>
-->
    <!-- ...................................... mobile Effort ...................................... -->
<!--
    <transmission name="trans_left_wheel_hinge">
        <type>transmission_interface/SimpleTransmission</type>
        <joint name="left_wheel_hinge">
            <hardwareInterface>hardware_interface/EffortJointInterface</hardwareInterface>
        </joint>
        <actuator name="left_wheel_hinge_motor">
            <hardwareInterface>hardware_interface/EffortJointInterface</hardwareInterface>
            <mechanicalReduction>1</mechanicalReduction>
        </actuator>
    </transmission>
    <transmission name="trans_right_wheel_hinge">
        <type>transmission_interface/SimpleTransmission</type>
        <joint name="right_wheel_hinge">
            <hardwareInterface>hardware_interface/EffortJointInterface</hardwareInterface>
        </joint>
        <actuator name="right_wheel_hinge_motor">
            <hardwareInterface>hardware_interface/EffortJointInterface</hardwareInterface>
            <mechanicalReduction>1</mechanicalReduction>
        </actuator>
    </transmission>
-->
    <!-- ...................................... arm Position ...................................... -->
    <transmission name="trans_joint1">
        <type>transmission_interface/SimpleTransmission</type>
        <joint name="joint1">
            <hardwareInterface>hardware_interface/PositionJointInterface</hardwareInterface>
        </joint>
        <actuator name="joint1_motor">
            <hardwareInterface>hardware_interface/PositionJointInterface</hardwareInterface>
            <mechanicalReduction>1</mechanicalReduction>
        </actuator>
    </transmission>
    <transmission name="trans_joint2">
        <type>transmission_interface/SimpleTransmission</type>
        <joint name="joint2">
            <hardwareInterface>hardware_interface/PositionJointInterface</hardwareInterface>
        </joint>
        <actuator name="joint2_motor">
            <hardwareInterface>hardware_interface/PositionJointInterface</hardwareInterface>
            <mechanicalReduction>1</mechanicalReduction>
        </actuator>
    </transmission>
    <transmission name="trans_joint3">
        <type>transmission_interface/SimpleTransmission</type>
        <joint name="joint3">
            <hardwareInterface>hardware_interface/PositionJointInterface</hardwareInterface>
        </joint>
        <actuator name="joint3_motor">
            <hardwareInterface>hardware_interface/PositionJointInterface</hardwareInterface>
            <mechanicalReduction>1</mechanicalReduction>
        </actuator>
    </transmission>
    <transmission name="trans_joint4">
        <type>transmission_interface/SimpleTransmission</type>
        <joint name="joint4">
            <hardwareInterface>hardware_interface/PositionJointInterface</hardwareInterface>
        </joint>
        <actuator name="joint4_motor">
            <hardwareInterface>hardware_interface/PositionJointInterface</hardwareInterface>
            <mechanicalReduction>1</mechanicalReduction>
        </actuator>
    </transmission>
    <transmission name="trans_joint5">
        <type>transmission_interface/SimpleTransmission</type>
        <joint name="joint5">
            <hardwareInterface>hardware_interface/PositionJointInterface</hardwareInterface>
        </joint>
        <actuator name="joint5_motor">
            <hardwareInterface>hardware_interface/PositionJointInterface</hardwareInterface>
            <mechanicalReduction>1</mechanicalReduction>
        </actuator>
    </transmission>
    <transmission name="trans_joint6">
        <type>transmission_interface/SimpleTransmission</type>
        <joint name="joint6">
            <hardwareInterface>hardware_interface/PositionJointInterface</hardwareInterface>
        </joint>
        <actuator name="joint6_motor">
            <hardwareInterface>hardware_interface/PositionJointInterface</hardwareInterface>
            <mechanicalReduction>1</mechanicalReduction>
        </actuator>
    </transmission>
    <!-- ...................................... MOBILE velocity ...................................... -->
    <transmission name="trans_left_wheel_hinge">
        <type>transmission_interface/SimpleTransmission</type>
        <joint name="left_wheel_hinge">
            <hardwareInterface>hardware_interface/VelocityJointInterface</hardwareInterface>
        </joint>
        <actuator name="left_wheel_hinge_motor">
            <hardwareInterface>hardware_interface/VelocityJointInterface</hardwareInterface>
            <mechanicalReduction>1</mechanicalReduction>
        </actuator>
    </transmission>
    <transmission name="trans_right_wheel_hinge">
        <type>transmission_interface/SimpleTransmission</type>
        <joint name="right_wheel_hinge">
            <hardwareInterface>hardware_interface/VelocityJointInterface</hardwareInterface>
        </joint>
        <actuator name="right_wheel_hinge_motor">
            <hardwareInterface>hardware_interface/VelocityJointInterface</hardwareInterface>
            <mechanicalReduction>1</mechanicalReduction>
        </actuator>
    </transmission>
    <!-- ...................................... ARM VELOCITY ...................................... -->
<!--
    <transmission name="trans_joint1">
        <type>transmission_interface/SimpleTransmission</type>
        <joint name="joint1">
            <hardwareInterface>hardware_interface/VelocityJointInterface</hardwareInterface>
        </joint>
        <actuator name="joint1_motor">
            <hardwareInterface>hardware_interface/VelocityJointInterface</hardwareInterface>
            <mechanicalReduction>1</mechanicalReduction>
        </actuator>
    </transmission>
    <transmission name="trans_joint2">
        <type>transmission_interface/SimpleTransmission</type>
        <joint name="joint2">
            <hardwareInterface>hardware_interface/VelocityJointInterface</hardwareInterface>
        </joint>
        <actuator name="joint2_motor">
            <hardwareInterface>hardware_interface/VelocityJointInterface</hardwareInterface>
            <mechanicalReduction>1</mechanicalReduction>
        </actuator>
    </transmission>
    <transmission name="trans_joint3">
        <type>transmission_interface/SimpleTransmission</type>
        <joint name="joint3">
            <hardwareInterface>hardware_interface/VelocityJointInterface</hardwareInterface>
        </joint>
        <actuator name="joint3_motor">
            <hardwareInterface>hardware_interface/VelocityJointInterface</hardwareInterface>
            <mechanicalReduction>1</mechanicalReduction>
        </actuator>
    </transmission>
    <transmission name="trans_joint4">
        <type>transmission_interface/SimpleTransmission</type>
        <joint name="joint4">
            <hardwareInterface>hardware_interface/VelocityJointInterface</hardwareInterface>
        </joint>
        <actuator name="joint4_motor">
            <hardwareInterface>hardware_interface/VelocityJointInterface</hardwareInterface>
            <mechanicalReduction>1</mechanicalReduction>
        </actuator>
    </transmission>
    <transmission name="trans_joint5">
        <type>transmission_interface/SimpleTransmission</type>
        <joint name="joint5">
            <hardwareInterface>hardware_interface/VelocityJointInterface</hardwareInterface>
        </joint>
        <actuator name="joint5_motor">
            <hardwareInterface>hardware_interface/VelocityJointInterface</hardwareInterface>
            <mechanicalReduction>1</mechanicalReduction>
        </actuator>
    </transmission>
    <transmission name="trans_joint6">
        <type>transmission_interface/SimpleTransmission</type>
        <joint name="joint6">
            <hardwareInterface>hardware_interface/VelocityJointInterface</hardwareInterface>
        </joint>
        <actuator name="joint6_motor">
            <hardwareInterface>hardware_interface/VelocityJointInterface</hardwareInterface>
            <mechanicalReduction>1</mechanicalReduction>
        </actuator>
    </transmission>
-->
    <!-- ........................ Casters ........................ -->
<!--
    <transmission name="trans_front_left_caster_hinge">
        <type>transmission_interface/SimpleTransmission</type>
        <joint name="front_left_caster_hinge">
            <hardwareInterface>hardware_interface/EffortJointInterface</hardwareInterface>
        </joint>
        <actuator name="front_left_caster_hinge_motor">
            <hardwareInterface>hardware_interface/EffortJointInterface</hardwareInterface>
            <mechanicalReduction>1</mechanicalReduction>
        </actuator>
    </transmission>
    <transmission name="trans_front_right_caster_hinge">
        <type>transmission_interface/SimpleTransmission</type>
        <joint name="front_right_caster_hinge">
            <hardwareInterface>hardware_interface/EffortJointInterface</hardwareInterface>
        </joint>
        <actuator name="front_right_caster_hinge_motor">
            <hardwareInterface>hardware_interface/EffortJointInterface</hardwareInterface>
            <mechanicalReduction>1</mechanicalReduction>
        </actuator>
    </transmission>
    <transmission name="trans_back_left_caster_hinge">
        <type>transmission_interface/SimpleTransmission</type>
        <joint name="back_left_caster_hinge">
            <hardwareInterface>hardware_interface/EffortJointInterface</hardwareInterface>
        </joint>
        <actuator name="back_left_caster_hinge_motor">
            <hardwareInterface>hardware_interface/EffortJointInterface</hardwareInterface>
            <mechanicalReduction>1</mechanicalReduction>
        </actuator>
    </transmission>
    <transmission name="trans_back_right_caster_hinge">
        <type>transmission_interface/SimpleTransmission</type>
        <joint name="back_right_caster_hinge">
            <hardwareInterface>hardware_interface/EffortJointInterface</hardwareInterface>
        </joint>
        <actuator name="back_right_caster_hinge_motor">
            <hardwareInterface>hardware_interface/EffortJointInterface</hardwareInterface>
            <mechanicalReduction>1</mechanicalReduction>
        </actuator>
    </transmission>   
    -->
    <!-- ........................ Gazebo state control ........................ -->
    <gazebo>
        <plugin name="gazebo_ros_control" filename="libgazebo_ros_control.so">
        <!-- -->
            <static>false</static> 
            <robotNamespace>/</robotNamespace>
            <robotSimType>gazebo_ros_control/DefaultRobotHWSim</robotSimType>
           <!-- -->
            <legacyModeNS>true</legacyModeNS>
        </plugin>
    </gazebo>

    
</robot>

<!-- ........................  ........................ -->

    <!--  -->
    <!--  -->
    <!--  -->
    <!--  -->
    <!--  -->
    <!--  -->
    <!--  -->
